{
  "nbformat": 4,
  "nbformat_minor": 0,
  "metadata": {
    "colab": {
      "provenance": [],
      "authorship_tag": "ABX9TyP2Q7VmHBKMO5HsZ5/FyOMv",
      "include_colab_link": true
    },
    "kernelspec": {
      "name": "python3",
      "display_name": "Python 3"
    },
    "language_info": {
      "name": "python"
    }
  },
  "cells": [
    {
      "cell_type": "markdown",
      "metadata": {
        "id": "view-in-github",
        "colab_type": "text"
      },
      "source": [
        "<a href=\"https://colab.research.google.com/github/Sheel23/assignment/blob/main/Assignment8.ipynb\" target=\"_parent\"><img src=\"https://colab.research.google.com/assets/colab-badge.svg\" alt=\"Open In Colab\"/></a>"
      ]
    },
    {
      "cell_type": "markdown",
      "source": [
        "##Q1. What is the role of try and exception block?\n",
        "\n",
        "Answers:-\n",
        "\n",
        "\n",
        "The role of the try and except block in Python is to handle and manage exceptions or errors that may occur during the execution of a program. Exceptions are events that occur during the execution of a program that disrupt the normal flow of the program.\n",
        "\n",
        "The try block is used to enclose the code that may potentially raise an exception. It allows you to specify a block of code where you anticipate potential errors or exceptions. If an exception occurs within the try block, the remaining code within the try block is skipped, and the program flow moves to the corresponding except block.\n",
        "\n",
        "The except block is used to handle specific types of exceptions. It specifies the code that should be executed when a particular exception occurs. You can have multiple except blocks to handle different types of exceptions. If an exception occurs within the try block that matches the type specified in the except block, the code within that except block is executed. If there is no matching except block, the exception is propagated up the call stack."
      ],
      "metadata": {
        "id": "yUoyGj8b6mbg"
      }
    },
    {
      "cell_type": "code",
      "execution_count": 3,
      "metadata": {
        "colab": {
          "base_uri": "https://localhost:8080/"
        },
        "id": "pOPdH7a56Ljh",
        "outputId": "2d72af5a-5869-47fc-e9d4-7e07325c5254"
      },
      "outputs": [
        {
          "output_type": "stream",
          "name": "stdout",
          "text": [
            "Error: Division by zero occurred!\n"
          ]
        }
      ],
      "source": [
        "# Example\n",
        "try:\n",
        "    # Code that may raise an exception\n",
        "    result = 10 / 0  # Division by zero\n",
        "    print(result)  # This line is skipped\n",
        "except ZeroDivisionError:\n",
        "    # Code to handle the ZeroDivisionError exception\n",
        "    print(\"Error: Division by zero occurred!\")\n"
      ]
    },
    {
      "cell_type": "markdown",
      "source": [
        "##Q2. What is the syntax for a basic try-except block?\n",
        "Answer :-\n",
        "\n",
        "In this syntax:\n",
        "\n",
        "The code that may raise an exception is enclosed within the try block.\n",
        "\n",
        "\n",
        "If an exception occurs within the try block, the code within the except block is executed.\n",
        "\n",
        "ExceptionType is the specific type of exception that you want to handle. It can be any built-in or user-defined exception class. If the exception raised within the try block matches the specified ExceptionType, the code within that except block is executed.\n",
        "\n",
        "You can have multiple except blocks to handle different types of exceptions. Each except block can handle a specific exception type.\n",
        "\n",
        "If an exception occurs that does not match any of the specified except blocks, it is propagated up the call stack. If there is no matching except block at any level, the program terminates with an unhandled exception error."
      ],
      "metadata": {
        "id": "Ky8qHr6p7Beo"
      }
    },
    {
      "cell_type": "code",
      "source": [
        "#Example\n",
        "try:\n",
        "    # Code that may raise an exception\n",
        "    x = 10 / 0  # Division by zero\n",
        "except ZeroDivisionError:\n",
        "    # Code to handle the ZeroDivisionError exception\n",
        "    print(\"Error: Division by zero occurred!\")\n"
      ],
      "metadata": {
        "colab": {
          "base_uri": "https://localhost:8080/"
        },
        "id": "WVZjBcSG61AI",
        "outputId": "c5e4978e-9344-4d6e-f640-b5ef73ea8167"
      },
      "execution_count": 4,
      "outputs": [
        {
          "output_type": "stream",
          "name": "stdout",
          "text": [
            "Error: Division by zero occurred!\n"
          ]
        }
      ]
    },
    {
      "cell_type": "markdown",
      "source": [
        "#Q.3 What happens if an exception occurs inside a try block and there is no matching except block?\n",
        "Answer:-\n",
        "\n",
        "If an exception occurs inside a try block and there is no matching except block to handle that exception, the exception is propagated up the call stack until a suitable exception handler is found. If no suitable exception handler is found at any level of the call stack, the program terminates, and an unhandled exception error is raised.\n",
        "\n",
        "When an exception occurs within a try block, the code execution within the try block is immediately interrupted, and the program flow moves to find a matching except block. If no matching except block is found within the same try-except block, the exception is not handled locally.\n",
        "\n",
        "The exception is then propagated up the call stack, meaning it moves to the next outer try-except block in the call hierarchy. If a matching except block is found at any level in the call stack, the corresponding exception handler code is executed, and the program continues to execute from that point.\n",
        "\n",
        "However, if the exception is not handled by any except block at any level, the program terminates abruptly, and an unhandled exception error is raised. This error message typically includes the details of the unhandled exception, such as the exception type, message, and the traceback showing the line of code where the exception occurred.\n",
        "\n",
        "It is generally recommended to handle exceptions appropriately by providing suitable except blocks to handle specific exception types or a more general except block to handle any exception that may occur. Proper exception handling ensures that your program can gracefully handle errors and continue execution, or take appropriate actions such as logging the error, displaying a meaningful message, or performing cleanup operations before termination."
      ],
      "metadata": {
        "id": "taSX1RRC8Eyg"
      }
    },
    {
      "cell_type": "markdown",
      "source": [
        "##Q4. What is the difference between using a bare except block and specifying a specific exception type?\n",
        "Answer:-\n",
        "\n",
        "The difference between using a bare except block and specifying a specific exception type lies in the level of specificity in exception handling.\n",
        "\n",
        "Bare except block:\n",
        "\n",
        "A bare except block is written as except: without specifying any exception type.\n",
        "It catches all types of exceptions, including both built-in and user-defined exceptions.\n",
        "It is a more general form of exception handling and is used when you want to catch any exception that may occur.\n",
        "It is less precise because it doesn't provide information about the specific exception type that occurred.\n",
        "It can make debugging more challenging as it can mask or hide specific exceptions.\n",
        "It should be used sparingly and with caution.\n",
        "\n",
        "Specific exception type:\n",
        "\n",
        "When you specify a specific exception type in an except block, such as except ValueError:, you are explicitly catching only that particular type of exception.\n",
        "The except block will only execute if the raised exception matches the specified exception type.\n",
        "It allows you to handle specific exceptions in a more controlled and targeted manner.\n",
        "It provides clarity and makes the code more readable by indicating which exceptions are being handled.\n",
        "It allows for more accurate debugging and error reporting."
      ],
      "metadata": {
        "id": "qicDCiX48R5L"
      }
    },
    {
      "cell_type": "code",
      "source": [
        "#example\n",
        "try:\n",
        "    x = int(\"abc\")  # Raises a ValueError\n",
        "except:\n",
        "    print(\"An error occurred!\")\n",
        "\n",
        "try:\n",
        "    x = int(\"abc\")  # Raises a ValueError\n",
        "except ValueError:\n",
        "    print(\"ValueError occurred!\")\n"
      ],
      "metadata": {
        "colab": {
          "base_uri": "https://localhost:8080/"
        },
        "id": "tOsI-oAn7ypW",
        "outputId": "9632e26e-7ed0-43d7-bc2c-a9d2d24ae757"
      },
      "execution_count": 6,
      "outputs": [
        {
          "output_type": "stream",
          "name": "stdout",
          "text": [
            "An error occurred!\n",
            "ValueError occurred!\n"
          ]
        }
      ]
    },
    {
      "cell_type": "markdown",
      "source": [
        "##5. Can you have nested try-except blocks in Python? If yes, then give an example.\n",
        "Answer:-\n",
        "\n",
        "you can have nested try-except blocks in Python. This means that you can have a try block inside another try block, and each try block can have its corresponding except block(s). Nesting try-except blocks allows you to handle exceptions at different levels of code execution and provide more specific error handling based on the context."
      ],
      "metadata": {
        "id": "JPwMAvo8OD-Q"
      }
    },
    {
      "cell_type": "code",
      "source": [
        "##Example\n",
        "try:\n",
        "    # Outer try block\n",
        "    x = 10 / 0  # Division by zero\n",
        "except ZeroDivisionError:\n",
        "    # Handling ZeroDivisionError in the outer try-except block\n",
        "    print(\"Error: Division by zero occurred!\")\n",
        "    try:\n",
        "        # Inner try block\n",
        "        y = int(\"abc\")  # ValueError: invalid literal for int()\n",
        "    except ValueError:\n",
        "        # Handling ValueError in the inner try-except block\n",
        "        print(\"Error: Invalid conversion to integer!\")\n"
      ],
      "metadata": {
        "colab": {
          "base_uri": "https://localhost:8080/"
        },
        "id": "A5c8tRmSNyV3",
        "outputId": "64bb7426-a958-4ea9-bb01-0c9b18c60670"
      },
      "execution_count": 7,
      "outputs": [
        {
          "output_type": "stream",
          "name": "stdout",
          "text": [
            "Error: Division by zero occurred!\n",
            "Error: Invalid conversion to integer!\n"
          ]
        }
      ]
    },
    {
      "cell_type": "markdown",
      "source": [
        "##Q6. Can we use multiple exception blocks, if yes then give an example.\n",
        "\n",
        " Answers:-\n",
        "\n",
        " We can use multiple except blocks to handle different types of exceptions in Python. This allows you to provide specific exception handling code for each type of exception that you anticipate or want to handle separately."
      ],
      "metadata": {
        "id": "QAsfGW8nOnlO"
      }
    },
    {
      "cell_type": "code",
      "source": [
        "#Example\n",
        "try:\n",
        "    # Code that may raise an exception\n",
        "    x = int(input(\"Enter a number: \"))\n",
        "    result = 10 / x\n",
        "    print(\"Result:\", result)\n",
        "except ValueError:\n",
        "    # Handling ValueError exception\n",
        "    print(\"Invalid input! Please enter a valid number.\")\n",
        "except ZeroDivisionError:\n",
        "    # Handling ZeroDivisionError exception\n",
        "    print(\"Error: Division by zero occurred!\")\n",
        "except Exception as e:\n",
        "    # Handling any other exception\n",
        "    print(\"An error occurred:\", str(e))\n"
      ],
      "metadata": {
        "colab": {
          "base_uri": "https://localhost:8080/"
        },
        "id": "dOEnIYeOOQIx",
        "outputId": "9b2bba7e-f568-4df3-b3ba-6b51e75a3fcf"
      },
      "execution_count": 8,
      "outputs": [
        {
          "output_type": "stream",
          "name": "stdout",
          "text": [
            "Enter a number: 4\n",
            "Result: 2.5\n"
          ]
        }
      ]
    },
    {
      "cell_type": "markdown",
      "source": [
        "The first except ValueError block handles a ValueError exception that may occur when converting the user input to an integer.\n",
        "The second except ZeroDivisionError block handles a ZeroDivisionError exception that may occur when dividing a number by zero.\n",
        "The third except Exception as e block is a catch-all block that handles any other type of exception not explicitly caught by the preceding except blocks. It captures the exception object into the variable e and prints a generic error message along with the exception details."
      ],
      "metadata": {
        "id": "qyvG_xpXO8Eb"
      }
    },
    {
      "cell_type": "markdown",
      "source": [
        "##7. Write the reason due to which following errors are raised:\n",
        "a. EOFError\n",
        "\n",
        "b. FloatingPointError\n",
        "\n",
        "c. IndexError\n",
        "\n",
        "d. MemoryError\n",
        "\n",
        "e. OverflowError\n",
        "\n",
        "f. TabError\n",
        "\n",
        "g. ValueError\n",
        "\n",
        "Answer:- The reasons for the following errors:\n",
        "\n",
        "a. EOFError:\n",
        "\n",
        "The EOFError is raised when the input() function reaches the end of the file (EOF) while trying to read input from the user or input stream.\n",
        "This error occurs when an expected input is not provided before the end of the input source.\n",
        "\n",
        "b. FloatingPointError:\n",
        "\n",
        "The FloatingPointError is raised when a floating-point operation fails to execute or results in an exceptional condition.\n",
        "This error occurs when there is an issue with floating-point arithmetic, such as dividing a number by zero or encountering an invalid operation.\n",
        "\n",
        "c. IndexError:\n",
        "\n",
        "The IndexError is raised when a sequence (e.g., list, tuple, string) is accessed using an invalid index that is outside the range of the sequence.\n",
        "This error occurs when you try to access an element using an index that does not exist within the sequence.\n",
        "\n",
        "d. MemoryError:\n",
        "\n",
        "The MemoryError is raised when the Python interpreter runs out of memory to allocate for a new object.\n",
        "This error occurs when the system does not have enough memory to fulfill the allocation request for an object.\n",
        "\n",
        "e. OverflowError:\n",
        "\n",
        "The OverflowError is raised when the result of an arithmetic operation exceeds the maximum representable value for a numeric type.\n",
        "This error occurs when performing calculations that produce a value outside the range that can be represented by the numeric type.\n",
        "\n",
        "f. TabError:\n",
        "\n",
        "The TabError is raised when there are inconsistent or incorrect uses of tabs and spaces for indentation.\n",
        "This error occurs when mixing tabs and spaces in indentation or when the indentation level is not consistent across the code.\n",
        "\n",
        "g. ValueError:\n",
        "\n",
        "The ValueError is raised when a function receives an argument of the correct type but an inappropriate value.\n",
        "This error occurs when an operation or function is called with an argument that is of the correct data type but is not a valid value for the operation or function."
      ],
      "metadata": {
        "id": "RjBIxHaePKlj"
      }
    },
    {
      "cell_type": "markdown",
      "source": [
        "##Q8. Write code for the following given scenario and add try-exception block to it.\n",
        "a. Program to divide two numbers\n",
        "\n",
        "b. Program to convert a string to an integer\n",
        "\n",
        "c. Program to access an element in a list\n",
        "\n",
        "d. Program to handle a specific exception\n",
        "\n",
        "e. Program to handle any exception\n",
        "\n",
        "Answer:-\n"
      ],
      "metadata": {
        "id": "OPrSadKdQTsJ"
      }
    },
    {
      "cell_type": "code",
      "source": [
        "#a. Program to divide two numbers\n",
        "try:\n",
        "    dividend = int(input(\"Enter the dividend: \"))\n",
        "    divisor = int(input(\"Enter the divisor: \"))\n",
        "    result = dividend / divisor\n",
        "    print(\"Result:\", result)\n",
        "except ZeroDivisionError:\n",
        "    print(\"Error: Division by zero is not allowed.\")\n",
        "except ValueError:\n",
        "    print(\"Error: Invalid input. Please enter integer values.\")\n"
      ],
      "metadata": {
        "colab": {
          "base_uri": "https://localhost:8080/"
        },
        "id": "agZ5sfJOO1Hl",
        "outputId": "73beb45b-063d-47ed-ea07-e3e46f94323a"
      },
      "execution_count": 9,
      "outputs": [
        {
          "output_type": "stream",
          "name": "stdout",
          "text": [
            "Enter the dividend: 2\n",
            "Enter the divisor: 4\n",
            "Result: 0.5\n"
          ]
        }
      ]
    },
    {
      "cell_type": "code",
      "source": [
        "#b. Program to convert a string to an integer:\n",
        "\n",
        "try:\n",
        "    number_str = input(\"Enter a number: \")\n",
        "    number = int(number_str)\n",
        "    print(\"Integer value:\", number)\n",
        "except ValueError:\n",
        "    print(\"Error: Invalid input. Please enter a valid integer.\")\n"
      ],
      "metadata": {
        "colab": {
          "base_uri": "https://localhost:8080/"
        },
        "id": "7BsLJcCtQoOg",
        "outputId": "f80e78ca-233e-4377-f2e5-48983b32c946"
      },
      "execution_count": 15,
      "outputs": [
        {
          "output_type": "stream",
          "name": "stdout",
          "text": [
            "Enter a number: 5\n",
            "Integer value: 5\n"
          ]
        }
      ]
    },
    {
      "cell_type": "code",
      "source": [
        "#c. Program to access an element in a list:\n",
        "\n",
        "try:\n",
        "    my_list = [1, 2, 3]\n",
        "    index = int(input(\"Enter the index: \"))\n",
        "    value = my_list[index]\n",
        "    print(\"Value at index\", index, \"is\", value)\n",
        "except IndexError:\n",
        "    print(\"Error: Index is out of range.\")\n",
        "except ValueError:\n",
        "    print(\"Error: Invalid input. Please enter an integer index.\")\n"
      ],
      "metadata": {
        "colab": {
          "base_uri": "https://localhost:8080/"
        },
        "id": "fqOAgwuBQxPu",
        "outputId": "8fcdcbd1-e0b5-4b80-b98a-4da6b0f42444"
      },
      "execution_count": 16,
      "outputs": [
        {
          "output_type": "stream",
          "name": "stdout",
          "text": [
            "Enter the index: 6\n",
            "Error: Index is out of range.\n"
          ]
        }
      ]
    },
    {
      "cell_type": "code",
      "source": [
        "#d. Program to handle a specific exception:\n",
        "\n",
        "try:\n",
        "    x = int(input(\"Enter a number: \"))\n",
        "    result = 10 / x\n",
        "    print(\"Result:\", result)\n",
        "except ZeroDivisionError:\n",
        "    print(\"Error: Division by zero occurred!\")\n",
        "except ValueError:\n",
        "    print(\"Error: Invalid input. Please enter a valid number.\")\n"
      ],
      "metadata": {
        "colab": {
          "base_uri": "https://localhost:8080/"
        },
        "id": "SFIH_UH5RAvJ",
        "outputId": "5d793f88-09ae-42e5-d5f6-bf66887e4d0c"
      },
      "execution_count": 13,
      "outputs": [
        {
          "output_type": "stream",
          "name": "stdout",
          "text": [
            "Enter a number: 4\n",
            "Result: 2.5\n"
          ]
        }
      ]
    },
    {
      "cell_type": "code",
      "source": [
        "#e. Program to handle any exception:\n",
        "\n",
        "try:\n",
        "    x = int(input(\"Enter a number: \"))\n",
        "    result = 10 / x\n",
        "    print(\"Result:\", result)\n",
        "except Exception as e:\n",
        "    print(\"An error occurred:\", str(e))\n"
      ],
      "metadata": {
        "colab": {
          "base_uri": "https://localhost:8080/"
        },
        "id": "Em-kcTzeRLgB",
        "outputId": "e2ac0fe6-b079-4cb9-8f5e-1810d11cc31f"
      },
      "execution_count": 14,
      "outputs": [
        {
          "output_type": "stream",
          "name": "stdout",
          "text": [
            "Enter a number: 6\n",
            "Result: 1.6666666666666667\n"
          ]
        }
      ]
    },
    {
      "cell_type": "code",
      "source": [],
      "metadata": {
        "id": "tJFIHhntRSxR"
      },
      "execution_count": null,
      "outputs": []
    }
  ]
}